<?xml version="1.0"?>
<!--
The URDF-file of the Panasonic VR-006L. Here the kinematic and geometric model
is generated for the ROS-driver. First all the links of the robot are specified, 
followed by the joints. 
-->
<robot name="panasonic">
<!--___________________Description of the colours_________________________-->

    <material name="black">
        <color rgba="0 0 0 1" />
    </material>

    <material name="red">
        <color rgba="0.8 0 0 1" />
    </material>


<!--____________________Description of the LINKS______________________________-->
    
    <link name= "base">
        <visual>
            <origin xyz="0 0 0" rpy="0 0 0" />
            <geometry>
                <mesh filename="package://panasonic_vr006l_support/meshes/cad/baseplatform.stl"
				scale=".01 .01 .01"/>
            </geometry>
            <material name="black" />
        </visual>
    </link>

    <link name= "link1">
        <visual>
            <origin xyz="0.01 0.014 0.042" rpy="0 0 -1.57" />
            <geometry>
                <mesh filename="package://panasonic_vr006l_support/meshes/cad/shoulder.stl"
				scale=".01 .01 .01"/>
            </geometry>
            <material name="black" />
        </visual>
    </link>

    <link name= "link2">
        <visual>
            <origin xyz="0 -0.03 0.16" rpy="0 0 1.57" />	<!-- -0.025 0 0.155 -->
            <geometry>
                <mesh filename="package://panasonic_vr006l_support/meshes/cad/upperarm_rotate.stl"
				scale=".01 .01 .01"/>
            </geometry>
            <material name="red" />
        </visual>
    </link>

    <link name= "link3">
        <visual>
            <origin xyz="0.01 0.06 0.04" rpy="0 0 1.57" />
            <geometry>
                <mesh filename="package://panasonic_vr006l_support/meshes/cad/elbow_new.stl"
				scale=".01 .01 .01"/>
            </geometry>
            <material name="red" />
        </visual>
    </link>

    <link name= "link4">
        <visual>
            <origin xyz="0.197 0 0.004" rpy="0 0 1.57 " />
            <geometry>
                <mesh filename="package://panasonic_vr006l_support/meshes/cad/forearm_new.stl"
				scale=".01 .01 .01"/>
            </geometry>
            <material name="red" />
        </visual>
    </link>

    <link name= "link5">
        <visual>
            <origin xyz="0.01 0 -0.008" rpy="1.55 0 1.57" />
            <geometry>
                <mesh filename="package://panasonic_vr006l_support/meshes/cad/frontend_rotate.stl"
				scale=".01 .01 .01"/>
            </geometry>
            <material name="red" />
        </visual>
    </link>

    <link name= "end_effector">
        <origin xyz= "0 0 0" />
    </link>

<!--________________________________Description of the JOINTS____________________________--> 
	
    <joint name="joint_base_link1" type="revolute">
        <parent link= "base"/>
        <child link= "link1"/>
        <origin xyz="0 0 0.06" rpy="0 0 0"/>
	    <axis xyz="0 0 1" />
	    <limit effort="100" lower="-2.705" upper="2.705" velocity="2.09" />
    </joint>

    <joint name="joint_link1_link2" type="revolute">
        <parent link= "link1"/>
        <child link= "link2"/>
       	<origin xyz="0.06 -0.048 0.072" rpy="0 0 0"/> <!-- -0.05 -0.058 0.080-->
	    <axis xyz="0 1 0 " />
	    <limit effort="100" lower="-1.745" upper="2.618" velocity="2.09" /> 
    </joint>
	
    <joint name="joint_link2_link3" type="revolute">
        <parent link= "link2"/>
        <child link= "link3"/>
	    <axis xyz="0 1 0" />
        <origin xyz="0 -0.002 0.243" rpy="0 0 0"/>
	    <limit effort="100" lower="-3" upper="1.3" velocity="2.09" />
    </joint>

    <joint name="joint_link3_link4" type="revolute">
        <parent link= "link3"/>
        <child link= "link4"/>
        <origin xyz="0.085 0.054 0.0425" rpy="0 0 0"/>
	    <axis xyz="1 0 0" />
	    <limit effort="100" lower="-3.316" upper="4.712" velocity="2.09" />
    </joint>

    <joint name="joint_link4_link5" type="revolute">
        <parent link= "link4"/>
        <child link= "link5"/>
        <origin xyz="0.265 0 0" rpy="0 0 0"/>
        <axis xyz="0 1 0" />
	    <limit effort="100" lower="-4.712" upper="4.712" velocity="5.23" />
    </joint>    

    <joint name="joint_link5_endeffector" type="revolute">
        <parent link="link5"/>
        <child link="end_effector"/>
        <origin xyz="0.02 0 -0.126" rpy= "0 0 0"/>
        <axis xyz= " 0 0 1"/>
		<limit effort="100" lower="-6.28" upper="6.28" velocity="5.23"/>
    </joint>

</robot>
